Error: 0b2975e5-a6b7-5125-ad57-3973ae53f6a3
Traceback (most resent call last):
  File "/workspaces/gufo_err/tests/test_traceback_samples.py", line 63, in test_format
    entry()
  File "/workspaces/gufo_err/tests/sample/trace.py", line 14, in entry
    to_oops()
  File "/workspaces/gufo_err/tests/sample/trace.py", line 8, in to_oops
    oops()
  File "/workspaces/gufo_err/tests/sample/trace.py", line 2, in oops
    raise RuntimeError("oops")
RuntimeError: oops
